root@ip-10-104-0-147:~/sealed-secrets# kubectl logs ef-matching-api-deployment-7d4f7d8774-2dp6f -n test
/usr/local/lib/python3.8/site-packages/ef_matching/heuristics_index/ghg_scope_heuristics/ghg_scope_heuristic_index_creator.py:14: UserWarning:
The version_base parameter is not specified.
Please specify a compatability version level, or None.
Will assume defaults for version 1.1
  with initialize_config_module(config_module="ef_matching.conf"):
2023-03-28 09:10:03,395 [INFO] ef_matching.feature_flags: ENV_TYPE = local
2023-03-28 09:10:03,399 [INFO] ef_matching.override_analysis: Logging level set to INFO
2023-03-28 09:10:03,404 [INFO] ef_matching.pipeline: Logging level set to INFO
BUILD_VERSION:c7f9d4d439d567348994b5542d91788c88301625
2023-03-28 09:10:03,474 [INFO] api.main: BUILD_VERSION:c7f9d4d439d567348994b5542d91788c88301625
--- Logging error ---
Traceback (most recent call last):
  File "/usr/local/lib/python3.8/site-packages/urllib3/connection.py", line 174, in _new_conn
    conn = connection.create_connection(
  File "/usr/local/lib/python3.8/site-packages/urllib3/util/connection.py", line 72, in create_connection
    for res in socket.getaddrinfo(host, port, family, socket.SOCK_STREAM):
  File "/usr/local/lib/python3.8/socket.py", line 918, in getaddrinfo
    for res in _socket.getaddrinfo(host, port, family, type, proto, flags):
socket.gaierror: [Errno -2] Name or service not known

During handling of the above exception, another exception occurred:

Traceback (most recent call last):
  File "/usr/local/lib/python3.8/site-packages/urllib3/connectionpool.py", line 703, in urlopen
    httplib_response = self._make_request(
  File "/usr/local/lib/python3.8/site-packages/urllib3/connectionpool.py", line 398, in _make_request
    conn.request(method, url, **httplib_request_kw)
  File "/usr/local/lib/python3.8/site-packages/urllib3/connection.py", line 239, in request
    super(HTTPConnection, self).request(method, url, body=body, headers=headers)
  File "/usr/local/lib/python3.8/http/client.py", line 1256, in request
    self._send_request(method, url, body, headers, encode_chunked)
  File "/usr/local/lib/python3.8/http/client.py", line 1302, in _send_request
    self.endheaders(body, encode_chunked=encode_chunked)
  File "/usr/local/lib/python3.8/http/client.py", line 1251, in endheaders
    self._send_output(message_body, encode_chunked=encode_chunked)
  File "/usr/local/lib/python3.8/http/client.py", line 1011, in _send_output
    self.send(msg)
  File "/usr/local/lib/python3.8/http/client.py", line 951, in send
    self.connect()
  File "/usr/local/lib/python3.8/site-packages/urllib3/connection.py", line 205, in connect
    conn = self._new_conn()
  File "/usr/local/lib/python3.8/site-packages/urllib3/connection.py", line 186, in _new_conn
    raise NewConnectionError(
urllib3.exceptions.NewConnectionError: <urllib3.connection.HTTPConnection object at 0x7f3ff754d6a0>: Failed to establish a new connection: [Errno -2] Name or service not known

During handling of the above exception, another exception occurred:

Traceback (most recent call last):
  File "/usr/local/lib/python3.8/site-packages/requests/adapters.py", line 489, in send
    resp = conn.urlopen(
  File "/usr/local/lib/python3.8/site-packages/urllib3/connectionpool.py", line 787, in urlopen
    retries = retries.increment(
  File "/usr/local/lib/python3.8/site-packages/urllib3/util/retry.py", line 592, in increment
    raise MaxRetryError(_pool, url, error or ResponseError(cause))
urllib3.exceptions.MaxRetryError: HTTPConnectionPool(host='log-collector-api-service', port=3001): Max retries exceeded with url: /logs (Caused by NewConnectionError('<urllib3.connection.HTTPConnection object at 0x7f3ff754d6a0>: Failed to establish a new connection: [Errno -2] Name or service not known'))

During handling of the above exception, another exception occurred:

Traceback (most recent call last):
  File "/code/src/api/logger/LogCollectorAPIHandler.py", line 19, in emit
    requests.post(
  File "/usr/local/lib/python3.8/site-packages/requests/api.py", line 115, in post
    return request("post", url, data=data, json=json, **kwargs)
  File "/usr/local/lib/python3.8/site-packages/requests/api.py", line 59, in request
    return session.request(method=method, url=url, **kwargs)
  File "/usr/local/lib/python3.8/site-packages/requests/sessions.py", line 587, in request
    resp = self.send(prep, **send_kwargs)
  File "/usr/local/lib/python3.8/site-packages/requests/sessions.py", line 701, in send
    r = adapter.send(request, **kwargs)
  File "/usr/local/lib/python3.8/site-packages/requests/adapters.py", line 565, in send
    raise ConnectionError(e, request=request)
requests.exceptions.ConnectionError: HTTPConnectionPool(host='log-collector-api-service', port=3001): Max retries exceeded with url: /logs (Caused by NewConnectionError('<urllib3.connection.HTTPConnection object at 0x7f3ff754d6a0>: Failed to establish a new connection: [Errno -2] Name or service not known'))
Call stack:
  File "/usr/local/lib/python3.8/runpy.py", line 194, in _run_module_as_main
    return _run_code(code, main_globals, None,
  File "/usr/local/lib/python3.8/runpy.py", line 87, in _run_code
    exec(code, run_globals)
  File "/code/src/api/__main__.py", line 4, in <module>
    start_app()
  File "/usr/local/lib/python3.8/site-packages/click/core.py", line 1128, in __call__
    return self.main(*args, **kwargs)
  File "/usr/local/lib/python3.8/site-packages/click/core.py", line 1053, in main
    rv = self.invoke(ctx)
  File "/usr/local/lib/python3.8/site-packages/click/core.py", line 1395, in invoke
    return ctx.invoke(self.callback, **ctx.params)
  File "/usr/local/lib/python3.8/site-packages/click/core.py", line 754, in invoke
    return __callback(*args, **kwargs)
  File "/code/src/api/__init__.py", line 33, in start_app
    uvicorn.run(app="api.main:app", workers=1, host="0.0.0.0", port=8000)
  File "/usr/local/lib/python3.8/site-packages/uvicorn/main.py", line 447, in run
    server.run()
  File "/usr/local/lib/python3.8/site-packages/uvicorn/server.py", line 68, in run
    return asyncio.run(self.serve(sockets=sockets))
  File "/usr/local/lib/python3.8/site-packages/nest_asyncio.py", line 35, in run
    return loop.run_until_complete(task)
  File "/usr/local/lib/python3.8/site-packages/nest_asyncio.py", line 84, in run_until_complete
    self._run_once()
  File "/usr/local/lib/python3.8/site-packages/nest_asyncio.py", line 120, in _run_once
    handle._run()
  File "/usr/local/lib/python3.8/asyncio/events.py", line 81, in _run
    self._context.run(self._callback, *self._args)
  File "/usr/local/lib/python3.8/site-packages/nest_asyncio.py", line 196, in step
    step_orig(task, exc)
  File "/usr/local/lib/python3.8/asyncio/tasks.py", line 280, in __step
    result = coro.send(None)
  File "/usr/local/lib/python3.8/site-packages/uvicorn/server.py", line 76, in serve
    config.load()
  File "/usr/local/lib/python3.8/site-packages/uvicorn/config.py", line 448, in load
    self.loaded_app = import_from_string(self.app)
  File "/usr/local/lib/python3.8/site-packages/uvicorn/importer.py", line 21, in import_from_string
    module = importlib.import_module(module_str)
  File "/usr/local/lib/python3.8/importlib/__init__.py", line 127, in import_module
    return _bootstrap._gcd_import(name[level:], package, level)
  File "<frozen importlib._bootstrap>", line 1014, in _gcd_import
  File "<frozen importlib._bootstrap>", line 991, in _find_and_load
  File "<frozen importlib._bootstrap>", line 975, in _find_and_load_unlocked
  File "<frozen importlib._bootstrap>", line 671, in _load_unlocked
  File "<frozen importlib._bootstrap_external>", line 843, in exec_module
  File "<frozen importlib._bootstrap>", line 219, in _call_with_frames_removed
  File "/code/src/api/main.py", line 58, in <module>
    logger.info(f"BUILD_VERSION:{build_version}")
  File "/usr/local/lib/python3.8/logging/__init__.py", line 1446, in info
    self._log(INFO, msg, args, **kwargs)
  File "/usr/local/lib/python3.8/logging/__init__.py", line 1589, in _log
    self.handle(record)
  File "/usr/local/lib/python3.8/logging/__init__.py", line 1599, in handle
    self.callHandlers(record)
  File "/usr/local/lib/python3.8/logging/__init__.py", line 1661, in callHandlers
    hdlr.handle(record)
  File "/usr/local/lib/python3.8/logging/__init__.py", line 954, in handle
    self.emit(record)
  File "/code/src/api/logger/LogCollectorAPIHandler.py", line 23, in emit
    self.handleError(record)
Message: 'BUILD_VERSION:c7f9d4d439d567348994b5542d91788c88301625'
Arguments: ()
Application Started
2023-03-28 09:10:04,164 [INFO] api.main: Application Started
--- Logging error ---
Traceback (most recent call last):
  File "/usr/local/lib/python3.8/site-packages/urllib3/connection.py", line 174, in _new_conn
    conn = connection.create_connection(
  File "/usr/local/lib/python3.8/site-packages/urllib3/util/connection.py", line 72, in create_connection
    for res in socket.getaddrinfo(host, port, family, socket.SOCK_STREAM):
  File "/usr/local/lib/python3.8/socket.py", line 918, in getaddrinfo
    for res in _socket.getaddrinfo(host, port, family, type, proto, flags):
socket.gaierror: [Errno -2] Name or service not known

During handling of the above exception, another exception occurred:

Traceback (most recent call last):
  File "/usr/local/lib/python3.8/site-packages/urllib3/connectionpool.py", line 703, in urlopen
    httplib_response = self._make_request(
  File "/usr/local/lib/python3.8/site-packages/urllib3/connectionpool.py", line 398, in _make_request
    conn.request(method, url, **httplib_request_kw)
  File "/usr/local/lib/python3.8/site-packages/urllib3/connection.py", line 239, in request
    super(HTTPConnection, self).request(method, url, body=body, headers=headers)
  File "/usr/local/lib/python3.8/http/client.py", line 1256, in request
    self._send_request(method, url, body, headers, encode_chunked)
  File "/usr/local/lib/python3.8/http/client.py", line 1302, in _send_request
    self.endheaders(body, encode_chunked=encode_chunked)
  File "/usr/local/lib/python3.8/http/client.py", line 1251, in endheaders
    self._send_output(message_body, encode_chunked=encode_chunked)
  File "/usr/local/lib/python3.8/http/client.py", line 1011, in _send_output
    self.send(msg)
  File "/usr/local/lib/python3.8/http/client.py", line 951, in send
    self.connect()
  File "/usr/local/lib/python3.8/site-packages/urllib3/connection.py", line 205, in connect
    conn = self._new_conn()
  File "/usr/local/lib/python3.8/site-packages/urllib3/connection.py", line 186, in _new_conn
    raise NewConnectionError(
urllib3.exceptions.NewConnectionError: <urllib3.connection.HTTPConnection object at 0x7f3ff7350be0>: Failed to establish a new connection: [Errno -2] Name or service not known

During handling of the above exception, another exception occurred:

Traceback (most recent call last):
  File "/usr/local/lib/python3.8/site-packages/requests/adapters.py", line 489, in send
    resp = conn.urlopen(
  File "/usr/local/lib/python3.8/site-packages/urllib3/connectionpool.py", line 787, in urlopen
    retries = retries.increment(
  File "/usr/local/lib/python3.8/site-packages/urllib3/util/retry.py", line 592, in increment
    raise MaxRetryError(_pool, url, error or ResponseError(cause))
urllib3.exceptions.MaxRetryError: HTTPConnectionPool(host='log-collector-api-service', port=3001): Max retries exceeded with url: /logs (Caused by NewConnectionError('<urllib3.connection.HTTPConnection object at 0x7f3ff7350be0>: Failed to establish a new connection: [Errno -2] Name or service not known'))

During handling of the above exception, another exception occurred:

Traceback (most recent call last):
  File "/code/src/api/logger/LogCollectorAPIHandler.py", line 19, in emit
    requests.post(
  File "/usr/local/lib/python3.8/site-packages/requests/api.py", line 115, in post
    return request("post", url, data=data, json=json, **kwargs)
  File "/usr/local/lib/python3.8/site-packages/requests/api.py", line 59, in request
    return session.request(method=method, url=url, **kwargs)
  File "/usr/local/lib/python3.8/site-packages/requests/sessions.py", line 587, in request
    resp = self.send(prep, **send_kwargs)
  File "/usr/local/lib/python3.8/site-packages/requests/sessions.py", line 701, in send
    r = adapter.send(request, **kwargs)
  File "/usr/local/lib/python3.8/site-packages/requests/adapters.py", line 565, in send
    raise ConnectionError(e, request=request)
requests.exceptions.ConnectionError: HTTPConnectionPool(host='log-collector-api-service', port=3001): Max retries exceeded with url: /logs (Caused by NewConnectionError('<urllib3.connection.HTTPConnection object at 0x7f3ff7350be0>: Failed to establish a new connection: [Errno -2] Name or service not known'))
Call stack:
  File "/usr/local/lib/python3.8/runpy.py", line 194, in _run_module_as_main
    return _run_code(code, main_globals, None,
  File "/usr/local/lib/python3.8/runpy.py", line 87, in _run_code
    exec(code, run_globals)
  File "/code/src/api/__main__.py", line 4, in <module>
    start_app()
  File "/usr/local/lib/python3.8/site-packages/click/core.py", line 1128, in __call__
    return self.main(*args, **kwargs)
  File "/usr/local/lib/python3.8/site-packages/click/core.py", line 1053, in main
    rv = self.invoke(ctx)
  File "/usr/local/lib/python3.8/site-packages/click/core.py", line 1395, in invoke
    return ctx.invoke(self.callback, **ctx.params)
  File "/usr/local/lib/python3.8/site-packages/click/core.py", line 754, in invoke
    return __callback(*args, **kwargs)
  File "/code/src/api/__init__.py", line 33, in start_app
    uvicorn.run(app="api.main:app", workers=1, host="0.0.0.0", port=8000)
  File "/usr/local/lib/python3.8/site-packages/uvicorn/main.py", line 447, in run
    server.run()
  File "/usr/local/lib/python3.8/site-packages/uvicorn/server.py", line 68, in run
    return asyncio.run(self.serve(sockets=sockets))
  File "/usr/local/lib/python3.8/site-packages/nest_asyncio.py", line 35, in run
    return loop.run_until_complete(task)
  File "/usr/local/lib/python3.8/site-packages/nest_asyncio.py", line 84, in run_until_complete
    self._run_once()
  File "/usr/local/lib/python3.8/site-packages/nest_asyncio.py", line 120, in _run_once
    handle._run()
  File "/usr/local/lib/python3.8/asyncio/events.py", line 81, in _run
    self._context.run(self._callback, *self._args)
  File "/usr/local/lib/python3.8/site-packages/nest_asyncio.py", line 196, in step
    step_orig(task, exc)
  File "/usr/local/lib/python3.8/asyncio/tasks.py", line 280, in __step
    result = coro.send(None)
  File "/usr/local/lib/python3.8/site-packages/uvicorn/server.py", line 76, in serve
    config.load()
  File "/usr/local/lib/python3.8/site-packages/uvicorn/config.py", line 448, in load
    self.loaded_app = import_from_string(self.app)
  File "/usr/local/lib/python3.8/site-packages/uvicorn/importer.py", line 21, in import_from_string
    module = importlib.import_module(module_str)
  File "/usr/local/lib/python3.8/importlib/__init__.py", line 127, in import_module
    return _bootstrap._gcd_import(name[level:], package, level)
  File "<frozen importlib._bootstrap>", line 1014, in _gcd_import
  File "<frozen importlib._bootstrap>", line 991, in _find_and_load
  File "<frozen importlib._bootstrap>", line 975, in _find_and_load_unlocked
  File "<frozen importlib._bootstrap>", line 671, in _load_unlocked
  File "<frozen importlib._bootstrap_external>", line 843, in exec_module
  File "<frozen importlib._bootstrap>", line 219, in _call_with_frames_removed
  File "/code/src/api/main.py", line 161, in <module>
    logger.info("Application Started")
  File "/usr/local/lib/python3.8/logging/__init__.py", line 1446, in info
    self._log(INFO, msg, args, **kwargs)
  File "/usr/local/lib/python3.8/logging/__init__.py", line 1589, in _log
    self.handle(record)
  File "/usr/local/lib/python3.8/logging/__init__.py", line 1599, in handle
    self.callHandlers(record)
  File "/usr/local/lib/python3.8/logging/__init__.py", line 1661, in callHandlers
    hdlr.handle(record)
  File "/usr/local/lib/python3.8/logging/__init__.py", line 954, in handle
    self.emit(record)
  File "/code/src/api/logger/LogCollectorAPIHandler.py", line 23, in emit
    self.handleError(record)
Message: 'Application Started'
Arguments: ()
INFO:     Started server process [1]
2023-03-28 09:10:04,171 [INFO] uvicorn.error: Started server process [1]
Started server process [1]
--- Logging error ---
Traceback (most recent call last):
  File "/usr/local/lib/python3.8/site-packages/urllib3/connection.py", line 174, in _new_conn
    conn = connection.create_connection(
  File "/usr/local/lib/python3.8/site-packages/urllib3/util/connection.py", line 72, in create_connection
    for res in socket.getaddrinfo(host, port, family, socket.SOCK_STREAM):
  File "/usr/local/lib/python3.8/socket.py", line 918, in getaddrinfo
    for res in _socket.getaddrinfo(host, port, family, type, proto, flags):
socket.gaierror: [Errno -2] Name or service not known

During handling of the above exception, another exception occurred:

Traceback (most recent call last):
  File "/usr/local/lib/python3.8/site-packages/urllib3/connectionpool.py", line 703, in urlopen
    httplib_response = self._make_request(
  File "/usr/local/lib/python3.8/site-packages/urllib3/connectionpool.py", line 398, in _make_request
    conn.request(method, url, **httplib_request_kw)
  File "/usr/local/lib/python3.8/site-packages/urllib3/connection.py", line 239, in request
    super(HTTPConnection, self).request(method, url, body=body, headers=headers)
  File "/usr/local/lib/python3.8/http/client.py", line 1256, in request
    self._send_request(method, url, body, headers, encode_chunked)
  File "/usr/local/lib/python3.8/http/client.py", line 1302, in _send_request
    self.endheaders(body, encode_chunked=encode_chunked)
  File "/usr/local/lib/python3.8/http/client.py", line 1251, in endheaders
    self._send_output(message_body, encode_chunked=encode_chunked)
  File "/usr/local/lib/python3.8/http/client.py", line 1011, in _send_output
    self.send(msg)
  File "/usr/local/lib/python3.8/http/client.py", line 951, in send
    self.connect()
  File "/usr/local/lib/python3.8/site-packages/urllib3/connection.py", line 205, in connect
    conn = self._new_conn()
  File "/usr/local/lib/python3.8/site-packages/urllib3/connection.py", line 186, in _new_conn
    raise NewConnectionError(
urllib3.exceptions.NewConnectionError: <urllib3.connection.HTTPConnection object at 0x7f3ff7350d30>: Failed to establish a new connection: [Errno -2] Name or service not known

During handling of the above exception, another exception occurred:

Traceback (most recent call last):
  File "/usr/local/lib/python3.8/site-packages/requests/adapters.py", line 489, in send
    resp = conn.urlopen(
  File "/usr/local/lib/python3.8/site-packages/urllib3/connectionpool.py", line 787, in urlopen
    retries = retries.increment(
  File "/usr/local/lib/python3.8/site-packages/urllib3/util/retry.py", line 592, in increment
    raise MaxRetryError(_pool, url, error or ResponseError(cause))
urllib3.exceptions.MaxRetryError: HTTPConnectionPool(host='log-collector-api-service', port=3001): Max retries exceeded with url: /logs (Caused by NewConnectionError('<urllib3.connection.HTTPConnection object at 0x7f3ff7350d30>: Failed to establish a new connection: [Errno -2] Name or service not known'))

During handling of the above exception, another exception occurred:

Traceback (most recent call last):
  File "/code/src/api/logger/LogCollectorAPIHandler.py", line 19, in emit
    requests.post(
  File "/usr/local/lib/python3.8/site-packages/requests/api.py", line 115, in post
    return request("post", url, data=data, json=json, **kwargs)
  File "/usr/local/lib/python3.8/site-packages/requests/api.py", line 59, in request
    return session.request(method=method, url=url, **kwargs)
  File "/usr/local/lib/python3.8/site-packages/requests/sessions.py", line 587, in request
    resp = self.send(prep, **send_kwargs)
  File "/usr/local/lib/python3.8/site-packages/requests/sessions.py", line 701, in send
    r = adapter.send(request, **kwargs)
  File "/usr/local/lib/python3.8/site-packages/requests/adapters.py", line 565, in send
    raise ConnectionError(e, request=request)
requests.exceptions.ConnectionError: HTTPConnectionPool(host='log-collector-api-service', port=3001): Max retries exceeded with url: /logs (Caused by NewConnectionError('<urllib3.connection.HTTPConnection object at 0x7f3ff7350d30>: Failed to establish a new connection: [Errno -2] Name or service not known'))
Call stack:
  File "/usr/local/lib/python3.8/runpy.py", line 194, in _run_module_as_main
    return _run_code(code, main_globals, None,
  File "/usr/local/lib/python3.8/runpy.py", line 87, in _run_code
    exec(code, run_globals)
  File "/code/src/api/__main__.py", line 4, in <module>
    start_app()
  File "/usr/local/lib/python3.8/site-packages/click/core.py", line 1128, in __call__
    return self.main(*args, **kwargs)
  File "/usr/local/lib/python3.8/site-packages/click/core.py", line 1053, in main
    rv = self.invoke(ctx)
  File "/usr/local/lib/python3.8/site-packages/click/core.py", line 1395, in invoke
    return ctx.invoke(self.callback, **ctx.params)
  File "/usr/local/lib/python3.8/site-packages/click/core.py", line 754, in invoke
    return __callback(*args, **kwargs)
  File "/code/src/api/__init__.py", line 33, in start_app
    uvicorn.run(app="api.main:app", workers=1, host="0.0.0.0", port=8000)
  File "/usr/local/lib/python3.8/site-packages/uvicorn/main.py", line 447, in run
    server.run()
  File "/usr/local/lib/python3.8/site-packages/uvicorn/server.py", line 68, in run
    return asyncio.run(self.serve(sockets=sockets))
  File "/usr/local/lib/python3.8/site-packages/nest_asyncio.py", line 35, in run
    return loop.run_until_complete(task)
  File "/usr/local/lib/python3.8/site-packages/nest_asyncio.py", line 84, in run_until_complete
    self._run_once()
  File "/usr/local/lib/python3.8/site-packages/nest_asyncio.py", line 120, in _run_once
    handle._run()
  File "/usr/local/lib/python3.8/asyncio/events.py", line 81, in _run
    self._context.run(self._callback, *self._args)
  File "/usr/local/lib/python3.8/site-packages/nest_asyncio.py", line 196, in step
    step_orig(task, exc)
  File "/usr/local/lib/python3.8/asyncio/tasks.py", line 280, in __step
    result = coro.send(None)
  File "/usr/local/lib/python3.8/site-packages/uvicorn/server.py", line 84, in serve
    logger.info(message, process_id, extra={"color_message": color_message})
  File "/usr/local/lib/python3.8/logging/__init__.py", line 1446, in info
    self._log(INFO, msg, args, **kwargs)
  File "/usr/local/lib/python3.8/logging/__init__.py", line 1589, in _log
    self.handle(record)
  File "/usr/local/lib/python3.8/logging/__init__.py", line 1599, in handle
    self.callHandlers(record)
  File "/usr/local/lib/python3.8/logging/__init__.py", line 1661, in callHandlers
    hdlr.handle(record)
  File "/usr/local/lib/python3.8/logging/__init__.py", line 954, in handle
    self.emit(record)
  File "/code/src/api/logger/LogCollectorAPIHandler.py", line 23, in emit
    self.handleError(record)
Message: 'Started server process [%d]'
Arguments: (1,)
INFO:     Waiting for application startup.
2023-03-28 09:10:04,176 [INFO] uvicorn.error: Waiting for application startup.
Waiting for application startup.
--- Logging error ---
Traceback (most recent call last):
  File "/usr/local/lib/python3.8/site-packages/urllib3/connection.py", line 174, in _new_conn
    conn = connection.create_connection(
  File "/usr/local/lib/python3.8/site-packages/urllib3/util/connection.py", line 72, in create_connection
    for res in socket.getaddrinfo(host, port, family, socket.SOCK_STREAM):
  File "/usr/local/lib/python3.8/socket.py", line 918, in getaddrinfo
    for res in _socket.getaddrinfo(host, port, family, type, proto, flags):
socket.gaierror: [Errno -2] Name or service not known

During handling of the above exception, another exception occurred:

Traceback (most recent call last):
  File "/usr/local/lib/python3.8/site-packages/urllib3/connectionpool.py", line 703, in urlopen
    httplib_response = self._make_request(
  File "/usr/local/lib/python3.8/site-packages/urllib3/connectionpool.py", line 398, in _make_request
    conn.request(method, url, **httplib_request_kw)
  File "/usr/local/lib/python3.8/site-packages/urllib3/connection.py", line 239, in request
    super(HTTPConnection, self).request(method, url, body=body, headers=headers)
  File "/usr/local/lib/python3.8/http/client.py", line 1256, in request
    self._send_request(method, url, body, headers, encode_chunked)
  File "/usr/local/lib/python3.8/http/client.py", line 1302, in _send_request
    self.endheaders(body, encode_chunked=encode_chunked)
  File "/usr/local/lib/python3.8/http/client.py", line 1251, in endheaders
    self._send_output(message_body, encode_chunked=encode_chunked)
  File "/usr/local/lib/python3.8/http/client.py", line 1011, in _send_output
    self.send(msg)
  File "/usr/local/lib/python3.8/http/client.py", line 951, in send
    self.connect()
  File "/usr/local/lib/python3.8/site-packages/urllib3/connection.py", line 205, in connect
    conn = self._new_conn()
  File "/usr/local/lib/python3.8/site-packages/urllib3/connection.py", line 186, in _new_conn
    raise NewConnectionError(
urllib3.exceptions.NewConnectionError: <urllib3.connection.HTTPConnection object at 0x7f3ff7350d60>: Failed to establish a new connection: [Errno -2] Name or service not known

During handling of the above exception, another exception occurred:

Traceback (most recent call last):
  File "/usr/local/lib/python3.8/site-packages/requests/adapters.py", line 489, in send
    resp = conn.urlopen(
  File "/usr/local/lib/python3.8/site-packages/urllib3/connectionpool.py", line 787, in urlopen
    retries = retries.increment(
  File "/usr/local/lib/python3.8/site-packages/urllib3/util/retry.py", line 592, in increment
    raise MaxRetryError(_pool, url, error or ResponseError(cause))
urllib3.exceptions.MaxRetryError: HTTPConnectionPool(host='log-collector-api-service', port=3001): Max retries exceeded with url: /logs (Caused by NewConnectionError('<urllib3.connection.HTTPConnection object at 0x7f3ff7350d60>: Failed to establish a new connection: [Errno -2] Name or service not known'))

During handling of the above exception, another exception occurred:

Traceback (most recent call last):
  File "/code/src/api/logger/LogCollectorAPIHandler.py", line 19, in emit
    requests.post(
  File "/usr/local/lib/python3.8/site-packages/requests/api.py", line 115, in post
    return request("post", url, data=data, json=json, **kwargs)
  File "/usr/local/lib/python3.8/site-packages/requests/api.py", line 59, in request
    return session.request(method=method, url=url, **kwargs)
  File "/usr/local/lib/python3.8/site-packages/requests/sessions.py", line 587, in request
    resp = self.send(prep, **send_kwargs)
  File "/usr/local/lib/python3.8/site-packages/requests/sessions.py", line 701, in send
    r = adapter.send(request, **kwargs)
  File "/usr/local/lib/python3.8/site-packages/requests/adapters.py", line 565, in send
    raise ConnectionError(e, request=request)
requests.exceptions.ConnectionError: HTTPConnectionPool(host='log-collector-api-service', port=3001): Max retries exceeded with url: /logs (Caused by NewConnectionError('<urllib3.connection.HTTPConnection object at 0x7f3ff7350d60>: Failed to establish a new connection: [Errno -2] Name or service not known'))
Call stack:
  File "/usr/local/lib/python3.8/runpy.py", line 194, in _run_module_as_main
    return _run_code(code, main_globals, None,
  File "/usr/local/lib/python3.8/runpy.py", line 87, in _run_code
    exec(code, run_globals)
  File "/code/src/api/__main__.py", line 4, in <module>
    start_app()
  File "/usr/local/lib/python3.8/site-packages/click/core.py", line 1128, in __call__
    return self.main(*args, **kwargs)
  File "/usr/local/lib/python3.8/site-packages/click/core.py", line 1053, in main
    rv = self.invoke(ctx)
  File "/usr/local/lib/python3.8/site-packages/click/core.py", line 1395, in invoke
    return ctx.invoke(self.callback, **ctx.params)
  File "/usr/local/lib/python3.8/site-packages/click/core.py", line 754, in invoke
    return __callback(*args, **kwargs)
  File "/code/src/api/__init__.py", line 33, in start_app
    uvicorn.run(app="api.main:app", workers=1, host="0.0.0.0", port=8000)
  File "/usr/local/lib/python3.8/site-packages/uvicorn/main.py", line 447, in run
    server.run()
  File "/usr/local/lib/python3.8/site-packages/uvicorn/server.py", line 68, in run
    return asyncio.run(self.serve(sockets=sockets))
  File "/usr/local/lib/python3.8/site-packages/nest_asyncio.py", line 35, in run
    return loop.run_until_complete(task)
  File "/usr/local/lib/python3.8/site-packages/nest_asyncio.py", line 84, in run_until_complete
    self._run_once()
  File "/usr/local/lib/python3.8/site-packages/nest_asyncio.py", line 120, in _run_once
    handle._run()
  File "/usr/local/lib/python3.8/asyncio/events.py", line 81, in _run
    self._context.run(self._callback, *self._args)
  File "/usr/local/lib/python3.8/site-packages/nest_asyncio.py", line 196, in step
    step_orig(task, exc)
  File "/usr/local/lib/python3.8/asyncio/tasks.py", line 280, in __step
    result = coro.send(None)
  File "/usr/local/lib/python3.8/site-packages/uvicorn/server.py", line 86, in serve
    await self.startup(sockets=sockets)
  File "/usr/local/lib/python3.8/site-packages/uvicorn/server.py", line 97, in startup
    await self.lifespan.startup()
  File "/usr/local/lib/python3.8/site-packages/uvicorn/lifespan/on.py", line 45, in startup
    self.logger.info("Waiting for application startup.")
  File "/usr/local/lib/python3.8/logging/__init__.py", line 1446, in info
    self._log(INFO, msg, args, **kwargs)
  File "/usr/local/lib/python3.8/logging/__init__.py", line 1589, in _log
    self.handle(record)
  File "/usr/local/lib/python3.8/logging/__init__.py", line 1599, in handle
    self.callHandlers(record)
  File "/usr/local/lib/python3.8/logging/__init__.py", line 1661, in callHandlers
    hdlr.handle(record)
  File "/usr/local/lib/python3.8/logging/__init__.py", line 954, in handle
    self.emit(record)
  File "/code/src/api/logger/LogCollectorAPIHandler.py", line 23, in emit
    self.handleError(record)
Message: 'Waiting for application startup.'
Arguments: ()
RabbitMQ queue selected
2023-03-28 09:10:04,183 [INFO] api.main: RabbitMQ queue selected
--- Logging error ---
Traceback (most recent call last):
  File "/usr/local/lib/python3.8/site-packages/urllib3/connection.py", line 174, in _new_conn
    conn = connection.create_connection(
  File "/usr/local/lib/python3.8/site-packages/urllib3/util/connection.py", line 72, in create_connection
    for res in socket.getaddrinfo(host, port, family, socket.SOCK_STREAM):
  File "/usr/local/lib/python3.8/socket.py", line 918, in getaddrinfo
    for res in _socket.getaddrinfo(host, port, family, type, proto, flags):
socket.gaierror: [Errno -2] Name or service not known

During handling of the above exception, another exception occurred:

Traceback (most recent call last):
  File "/usr/local/lib/python3.8/site-packages/urllib3/connectionpool.py", line 703, in urlopen
    httplib_response = self._make_request(
  File "/usr/local/lib/python3.8/site-packages/urllib3/connectionpool.py", line 398, in _make_request
    conn.request(method, url, **httplib_request_kw)
  File "/usr/local/lib/python3.8/site-packages/urllib3/connection.py", line 239, in request
    super(HTTPConnection, self).request(method, url, body=body, headers=headers)
  File "/usr/local/lib/python3.8/http/client.py", line 1256, in request
    self._send_request(method, url, body, headers, encode_chunked)
  File "/usr/local/lib/python3.8/http/client.py", line 1302, in _send_request
    self.endheaders(body, encode_chunked=encode_chunked)
  File "/usr/local/lib/python3.8/http/client.py", line 1251, in endheaders
    self._send_output(message_body, encode_chunked=encode_chunked)
  File "/usr/local/lib/python3.8/http/client.py", line 1011, in _send_output
    self.send(msg)
  File "/usr/local/lib/python3.8/http/client.py", line 951, in send
    self.connect()
  File "/usr/local/lib/python3.8/site-packages/urllib3/connection.py", line 205, in connect
    conn = self._new_conn()
  File "/usr/local/lib/python3.8/site-packages/urllib3/connection.py", line 186, in _new_conn
    raise NewConnectionError(
urllib3.exceptions.NewConnectionError: <urllib3.connection.HTTPConnection object at 0x7f3ff7350f10>: Failed to establish a new connection: [Errno -2] Name or service not known

During handling of the above exception, another exception occurred:

Traceback (most recent call last):
  File "/usr/local/lib/python3.8/site-packages/requests/adapters.py", line 489, in send
    resp = conn.urlopen(
  File "/usr/local/lib/python3.8/site-packages/urllib3/connectionpool.py", line 787, in urlopen
    retries = retries.increment(
  File "/usr/local/lib/python3.8/site-packages/urllib3/util/retry.py", line 592, in increment
    raise MaxRetryError(_pool, url, error or ResponseError(cause))
urllib3.exceptions.MaxRetryError: HTTPConnectionPool(host='log-collector-api-service', port=3001): Max retries exceeded with url: /logs (Caused by NewConnectionError('<urllib3.connection.HTTPConnection object at 0x7f3ff7350f10>: Failed to establish a new connection: [Errno -2] Name or service not known'))

During handling of the above exception, another exception occurred:

Traceback (most recent call last):
  File "/code/src/api/logger/LogCollectorAPIHandler.py", line 19, in emit
    requests.post(
  File "/usr/local/lib/python3.8/site-packages/requests/api.py", line 115, in post
    return request("post", url, data=data, json=json, **kwargs)
  File "/usr/local/lib/python3.8/site-packages/requests/api.py", line 59, in request
    return session.request(method=method, url=url, **kwargs)
  File "/usr/local/lib/python3.8/site-packages/requests/sessions.py", line 587, in request
    resp = self.send(prep, **send_kwargs)
  File "/usr/local/lib/python3.8/site-packages/requests/sessions.py", line 701, in send
    r = adapter.send(request, **kwargs)
  File "/usr/local/lib/python3.8/site-packages/requests/adapters.py", line 565, in send
    raise ConnectionError(e, request=request)
requests.exceptions.ConnectionError: HTTPConnectionPool(host='log-collector-api-service', port=3001): Max retries exceeded with url: /logs (Caused by NewConnectionError('<urllib3.connection.HTTPConnection object at 0x7f3ff7350f10>: Failed to establish a new connection: [Errno -2] Name or service not known'))
Call stack:
  File "/usr/local/lib/python3.8/runpy.py", line 194, in _run_module_as_main
    return _run_code(code, main_globals, None,
  File "/usr/local/lib/python3.8/runpy.py", line 87, in _run_code
    exec(code, run_globals)
  File "/code/src/api/__main__.py", line 4, in <module>
    start_app()
  File "/usr/local/lib/python3.8/site-packages/click/core.py", line 1128, in __call__
    return self.main(*args, **kwargs)
  File "/usr/local/lib/python3.8/site-packages/click/core.py", line 1053, in main
    rv = self.invoke(ctx)
  File "/usr/local/lib/python3.8/site-packages/click/core.py", line 1395, in invoke
    return ctx.invoke(self.callback, **ctx.params)
  File "/usr/local/lib/python3.8/site-packages/click/core.py", line 754, in invoke
    return __callback(*args, **kwargs)
  File "/code/src/api/__init__.py", line 33, in start_app
    uvicorn.run(app="api.main:app", workers=1, host="0.0.0.0", port=8000)
  File "/usr/local/lib/python3.8/site-packages/uvicorn/main.py", line 447, in run
    server.run()
  File "/usr/local/lib/python3.8/site-packages/uvicorn/server.py", line 68, in run
    return asyncio.run(self.serve(sockets=sockets))
  File "/usr/local/lib/python3.8/site-packages/nest_asyncio.py", line 35, in run
    return loop.run_until_complete(task)
  File "/usr/local/lib/python3.8/site-packages/nest_asyncio.py", line 84, in run_until_complete
    self._run_once()
  File "/usr/local/lib/python3.8/site-packages/nest_asyncio.py", line 120, in _run_once
    handle._run()
  File "/usr/local/lib/python3.8/asyncio/events.py", line 81, in _run
    self._context.run(self._callback, *self._args)
  File "/usr/local/lib/python3.8/site-packages/nest_asyncio.py", line 196, in step
    step_orig(task, exc)
  File "/usr/local/lib/python3.8/asyncio/tasks.py", line 280, in __step
    result = coro.send(None)
  File "/usr/local/lib/python3.8/site-packages/uvicorn/lifespan/on.py", line 84, in main
    await app(scope, self.receive, self.send)
  File "/usr/local/lib/python3.8/site-packages/uvicorn/middleware/proxy_headers.py", line 75, in __call__
    return await self.app(scope, receive, send)
  File "/usr/local/lib/python3.8/site-packages/fastapi/applications.py", line 208, in __call__
    await super().__call__(scope, receive, send)
  File "/usr/local/lib/python3.8/site-packages/starlette/applications.py", line 112, in __call__
    await self.middleware_stack(scope, receive, send)
  File "/usr/local/lib/python3.8/site-packages/starlette/middleware/errors.py", line 146, in __call__
    await self.app(scope, receive, send)
  File "/usr/local/lib/python3.8/site-packages/starlette/exceptions.py", line 58, in __call__
    await self.app(scope, receive, send)
  File "/usr/local/lib/python3.8/site-packages/starlette/routing.py", line 645, in __call__
    await self.lifespan(scope, receive, send)
  File "/usr/local/lib/python3.8/site-packages/starlette/routing.py", line 621, in lifespan
    async with self.lifespan_context(app):
  File "/usr/local/lib/python3.8/site-packages/starlette/routing.py", line 518, in __aenter__
    await self._router.startup()
  File "/usr/local/lib/python3.8/site-packages/starlette/routing.py", line 598, in startup
    await handler()
  File "/code/src/api/main.py", line 136, in startup_event
    logger.info("RabbitMQ queue selected")
  File "/usr/local/lib/python3.8/logging/__init__.py", line 1446, in info
    self._log(INFO, msg, args, **kwargs)
  File "/usr/local/lib/python3.8/logging/__init__.py", line 1589, in _log
    self.handle(record)
  File "/usr/local/lib/python3.8/logging/__init__.py", line 1599, in handle
    self.callHandlers(record)
  File "/usr/local/lib/python3.8/logging/__init__.py", line 1661, in callHandlers
    hdlr.handle(record)
  File "/usr/local/lib/python3.8/logging/__init__.py", line 954, in handle
    self.emit(record)
  File "/code/src/api/logger/LogCollectorAPIHandler.py", line 23, in emit
    self.handleError(record)
Message: 'RabbitMQ queue selected'
Arguments: ()
2023-03-28 09:10:04,193 [INFO] api.message_queues.rabbitmq.message_queue: Setting up connection
Setting up connection
--- Logging error ---
Traceback (most recent call last):
  File "/usr/local/lib/python3.8/site-packages/urllib3/connection.py", line 174, in _new_conn
    conn = connection.create_connection(
  File "/usr/local/lib/python3.8/site-packages/urllib3/util/connection.py", line 72, in create_connection
    for res in socket.getaddrinfo(host, port, family, socket.SOCK_STREAM):
  File "/usr/local/lib/python3.8/socket.py", line 918, in getaddrinfo
    for res in _socket.getaddrinfo(host, port, family, type, proto, flags):
socket.gaierror: [Errno -2] Name or service not known

During handling of the above exception, another exception occurred:

Traceback (most recent call last):
  File "/usr/local/lib/python3.8/site-packages/urllib3/connectionpool.py", line 703, in urlopen
    httplib_response = self._make_request(
  File "/usr/local/lib/python3.8/site-packages/urllib3/connectionpool.py", line 398, in _make_request
    conn.request(method, url, **httplib_request_kw)
  File "/usr/local/lib/python3.8/site-packages/urllib3/connection.py", line 239, in request
    super(HTTPConnection, self).request(method, url, body=body, headers=headers)
  File "/usr/local/lib/python3.8/http/client.py", line 1256, in request
    self._send_request(method, url, body, headers, encode_chunked)
  File "/usr/local/lib/python3.8/http/client.py", line 1302, in _send_request
    self.endheaders(body, encode_chunked=encode_chunked)
  File "/usr/local/lib/python3.8/http/client.py", line 1251, in endheaders
    self._send_output(message_body, encode_chunked=encode_chunked)
  File "/usr/local/lib/python3.8/http/client.py", line 1011, in _send_output
    self.send(msg)
  File "/usr/local/lib/python3.8/http/client.py", line 951, in send
    self.connect()
  File "/usr/local/lib/python3.8/site-packages/urllib3/connection.py", line 205, in connect
    conn = self._new_conn()
  File "/usr/local/lib/python3.8/site-packages/urllib3/connection.py", line 186, in _new_conn
    raise NewConnectionError(
urllib3.exceptions.NewConnectionError: <urllib3.connection.HTTPConnection object at 0x7f3ff7350c70>: Failed to establish a new connection: [Errno -2] Name or service not known

During handling of the above exception, another exception occurred:

Traceback (most recent call last):
  File "/usr/local/lib/python3.8/site-packages/requests/adapters.py", line 489, in send
    resp = conn.urlopen(
  File "/usr/local/lib/python3.8/site-packages/urllib3/connectionpool.py", line 787, in urlopen
    retries = retries.increment(
  File "/usr/local/lib/python3.8/site-packages/urllib3/util/retry.py", line 592, in increment
    raise MaxRetryError(_pool, url, error or ResponseError(cause))
urllib3.exceptions.MaxRetryError: HTTPConnectionPool(host='log-collector-api-service', port=3001): Max retries exceeded with url: /logs (Caused by NewConnectionError('<urllib3.connection.HTTPConnection object at 0x7f3ff7350c70>: Failed to establish a new connection: [Errno -2] Name or service not known'))

During handling of the above exception, another exception occurred:

Traceback (most recent call last):
  File "/code/src/api/logger/LogCollectorAPIHandler.py", line 19, in emit
    requests.post(
  File "/usr/local/lib/python3.8/site-packages/requests/api.py", line 115, in post
    return request("post", url, data=data, json=json, **kwargs)
  File "/usr/local/lib/python3.8/site-packages/requests/api.py", line 59, in request
    return session.request(method=method, url=url, **kwargs)
  File "/usr/local/lib/python3.8/site-packages/requests/sessions.py", line 587, in request
    resp = self.send(prep, **send_kwargs)
  File "/usr/local/lib/python3.8/site-packages/requests/sessions.py", line 701, in send
    r = adapter.send(request, **kwargs)
  File "/usr/local/lib/python3.8/site-packages/requests/adapters.py", line 565, in send
    raise ConnectionError(e, request=request)
requests.exceptions.ConnectionError: HTTPConnectionPool(host='log-collector-api-service', port=3001): Max retries exceeded with url: /logs (Caused by NewConnectionError('<urllib3.connection.HTTPConnection object at 0x7f3ff7350c70>: Failed to establish a new connection: [Errno -2] Name or service not known'))
Call stack:
  File "/usr/local/lib/python3.8/runpy.py", line 194, in _run_module_as_main
    return _run_code(code, main_globals, None,
  File "/usr/local/lib/python3.8/runpy.py", line 87, in _run_code
    exec(code, run_globals)
  File "/code/src/api/__main__.py", line 4, in <module>
    start_app()
  File "/usr/local/lib/python3.8/site-packages/click/core.py", line 1128, in __call__
    return self.main(*args, **kwargs)
  File "/usr/local/lib/python3.8/site-packages/click/core.py", line 1053, in main
    rv = self.invoke(ctx)
  File "/usr/local/lib/python3.8/site-packages/click/core.py", line 1395, in invoke
    return ctx.invoke(self.callback, **ctx.params)
  File "/usr/local/lib/python3.8/site-packages/click/core.py", line 754, in invoke
    return __callback(*args, **kwargs)
  File "/code/src/api/__init__.py", line 33, in start_app
    uvicorn.run(app="api.main:app", workers=1, host="0.0.0.0", port=8000)
  File "/usr/local/lib/python3.8/site-packages/uvicorn/main.py", line 447, in run
    server.run()
  File "/usr/local/lib/python3.8/site-packages/uvicorn/server.py", line 68, in run
    return asyncio.run(self.serve(sockets=sockets))
  File "/usr/local/lib/python3.8/site-packages/nest_asyncio.py", line 35, in run
    return loop.run_until_complete(task)
  File "/usr/local/lib/python3.8/site-packages/nest_asyncio.py", line 84, in run_until_complete
    self._run_once()
  File "/usr/local/lib/python3.8/site-packages/nest_asyncio.py", line 120, in _run_once
    handle._run()
  File "/usr/local/lib/python3.8/asyncio/events.py", line 81, in _run
    self._context.run(self._callback, *self._args)
  File "/usr/local/lib/python3.8/site-packages/nest_asyncio.py", line 196, in step
    step_orig(task, exc)
  File "/usr/local/lib/python3.8/asyncio/tasks.py", line 280, in __step
    result = coro.send(None)
  File "/usr/local/lib/python3.8/site-packages/uvicorn/lifespan/on.py", line 84, in main
    await app(scope, self.receive, self.send)
  File "/usr/local/lib/python3.8/site-packages/uvicorn/middleware/proxy_headers.py", line 75, in __call__
    return await self.app(scope, receive, send)
  File "/usr/local/lib/python3.8/site-packages/fastapi/applications.py", line 208, in __call__
    await super().__call__(scope, receive, send)
  File "/usr/local/lib/python3.8/site-packages/starlette/applications.py", line 112, in __call__
    await self.middleware_stack(scope, receive, send)
  File "/usr/local/lib/python3.8/site-packages/starlette/middleware/errors.py", line 146, in __call__
    await self.app(scope, receive, send)
  File "/usr/local/lib/python3.8/site-packages/starlette/exceptions.py", line 58, in __call__
    await self.app(scope, receive, send)
  File "/usr/local/lib/python3.8/site-packages/starlette/routing.py", line 645, in __call__
    await self.lifespan(scope, receive, send)
  File "/usr/local/lib/python3.8/site-packages/starlette/routing.py", line 621, in lifespan
    async with self.lifespan_context(app):
  File "/usr/local/lib/python3.8/site-packages/starlette/routing.py", line 518, in __aenter__
    await self._router.startup()
  File "/usr/local/lib/python3.8/site-packages/starlette/routing.py", line 598, in startup
    await handler()
  File "/code/src/api/main.py", line 137, in startup_event
    queue = await RabbitMQQueue.setupConnection(
  File "/code/src/api/message_queues/rabbitmq/message_queue.py", line 26, in setupConnection
    logger.info("Setting up connection")
  File "/usr/local/lib/python3.8/logging/__init__.py", line 1446, in info
    self._log(INFO, msg, args, **kwargs)
  File "/usr/local/lib/python3.8/logging/__init__.py", line 1589, in _log
    self.handle(record)
  File "/usr/local/lib/python3.8/logging/__init__.py", line 1599, in handle
    self.callHandlers(record)
  File "/usr/local/lib/python3.8/logging/__init__.py", line 1661, in callHandlers
    hdlr.handle(record)
  File "/usr/local/lib/python3.8/logging/__init__.py", line 954, in handle
    self.emit(record)
  File "/code/src/api/logger/LogCollectorAPIHandler.py", line 23, in emit
    self.handleError(record)
Message: 'Setting up connection'
Arguments: ()
2023-03-28 09:10:04,233 [INFO] api.message_queues.rabbitmq.message_queue: Connected
Connected
--- Logging error ---
Traceback (most recent call last):
  File "/usr/local/lib/python3.8/site-packages/urllib3/connection.py", line 174, in _new_conn
    conn = connection.create_connection(
  File "/usr/local/lib/python3.8/site-packages/urllib3/util/connection.py", line 72, in create_connection
    for res in socket.getaddrinfo(host, port, family, socket.SOCK_STREAM):
  File "/usr/local/lib/python3.8/socket.py", line 918, in getaddrinfo
    for res in _socket.getaddrinfo(host, port, family, type, proto, flags):
socket.gaierror: [Errno -2] Name or service not known

During handling of the above exception, another exception occurred:

Traceback (most recent call last):
  File "/usr/local/lib/python3.8/site-packages/urllib3/connectionpool.py", line 703, in urlopen
    httplib_response = self._make_request(
  File "/usr/local/lib/python3.8/site-packages/urllib3/connectionpool.py", line 398, in _make_request
    conn.request(method, url, **httplib_request_kw)
  File "/usr/local/lib/python3.8/site-packages/urllib3/connection.py", line 239, in request
    super(HTTPConnection, self).request(method, url, body=body, headers=headers)
  File "/usr/local/lib/python3.8/http/client.py", line 1256, in request
    self._send_request(method, url, body, headers, encode_chunked)
  File "/usr/local/lib/python3.8/http/client.py", line 1302, in _send_request
    self.endheaders(body, encode_chunked=encode_chunked)
  File "/usr/local/lib/python3.8/http/client.py", line 1251, in endheaders
    self._send_output(message_body, encode_chunked=encode_chunked)
  File "/usr/local/lib/python3.8/http/client.py", line 1011, in _send_output
    self.send(msg)
  File "/usr/local/lib/python3.8/http/client.py", line 951, in send
    self.connect()
  File "/usr/local/lib/python3.8/site-packages/urllib3/connection.py", line 205, in connect
    conn = self._new_conn()
  File "/usr/local/lib/python3.8/site-packages/urllib3/connection.py", line 186, in _new_conn
    raise NewConnectionError(
urllib3.exceptions.NewConnectionError: <urllib3.connection.HTTPConnection object at 0x7f3ff68b1040>: Failed to establish a new connection: [Errno -2] Name or service not known

During handling of the above exception, another exception occurred:

Traceback (most recent call last):
  File "/usr/local/lib/python3.8/site-packages/requests/adapters.py", line 489, in send
    resp = conn.urlopen(
  File "/usr/local/lib/python3.8/site-packages/urllib3/connectionpool.py", line 787, in urlopen
    retries = retries.increment(
  File "/usr/local/lib/python3.8/site-packages/urllib3/util/retry.py", line 592, in increment
    raise MaxRetryError(_pool, url, error or ResponseError(cause))
urllib3.exceptions.MaxRetryError: HTTPConnectionPool(host='log-collector-api-service', port=3001): Max retries exceeded with url: /logs (Caused by NewConnectionError('<urllib3.connection.HTTPConnection object at 0x7f3ff68b1040>: Failed to establish a new connection: [Errno -2] Name or service not known'))

During handling of the above exception, another exception occurred:

Traceback (most recent call last):
  File "/code/src/api/logger/LogCollectorAPIHandler.py", line 19, in emit
    requests.post(
  File "/usr/local/lib/python3.8/site-packages/requests/api.py", line 115, in post
    return request("post", url, data=data, json=json, **kwargs)
  File "/usr/local/lib/python3.8/site-packages/requests/api.py", line 59, in request
    return session.request(method=method, url=url, **kwargs)
  File "/usr/local/lib/python3.8/site-packages/requests/sessions.py", line 587, in request
    resp = self.send(prep, **send_kwargs)
  File "/usr/local/lib/python3.8/site-packages/requests/sessions.py", line 701, in send
    r = adapter.send(request, **kwargs)
  File "/usr/local/lib/python3.8/site-packages/requests/adapters.py", line 565, in send
    raise ConnectionError(e, request=request)
requests.exceptions.ConnectionError: HTTPConnectionPool(host='log-collector-api-service', port=3001): Max retries exceeded with url: /logs (Caused by NewConnectionError('<urllib3.connection.HTTPConnection object at 0x7f3ff68b1040>: Failed to establish a new connection: [Errno -2] Name or service not known'))
Call stack:
  File "/usr/local/lib/python3.8/runpy.py", line 194, in _run_module_as_main
    return _run_code(code, main_globals, None,
  File "/usr/local/lib/python3.8/runpy.py", line 87, in _run_code
    exec(code, run_globals)
  File "/code/src/api/__main__.py", line 4, in <module>
    start_app()
  File "/usr/local/lib/python3.8/site-packages/click/core.py", line 1128, in __call__
    return self.main(*args, **kwargs)
  File "/usr/local/lib/python3.8/site-packages/click/core.py", line 1053, in main
    rv = self.invoke(ctx)
  File "/usr/local/lib/python3.8/site-packages/click/core.py", line 1395, in invoke
    return ctx.invoke(self.callback, **ctx.params)
  File "/usr/local/lib/python3.8/site-packages/click/core.py", line 754, in invoke
    return __callback(*args, **kwargs)
  File "/code/src/api/__init__.py", line 33, in start_app
    uvicorn.run(app="api.main:app", workers=1, host="0.0.0.0", port=8000)
  File "/usr/local/lib/python3.8/site-packages/uvicorn/main.py", line 447, in run
    server.run()
  File "/usr/local/lib/python3.8/site-packages/uvicorn/server.py", line 68, in run
    return asyncio.run(self.serve(sockets=sockets))
  File "/usr/local/lib/python3.8/site-packages/nest_asyncio.py", line 35, in run
    return loop.run_until_complete(task)
  File "/usr/local/lib/python3.8/site-packages/nest_asyncio.py", line 84, in run_until_complete
    self._run_once()
  File "/usr/local/lib/python3.8/site-packages/nest_asyncio.py", line 120, in _run_once
    handle._run()
  File "/usr/local/lib/python3.8/asyncio/events.py", line 81, in _run
    self._context.run(self._callback, *self._args)
  File "/usr/local/lib/python3.8/asyncio/tasks.py", line 360, in __wakeup
    self.__step()
  File "/usr/local/lib/python3.8/site-packages/nest_asyncio.py", line 196, in step
    step_orig(task, exc)
  File "/usr/local/lib/python3.8/asyncio/tasks.py", line 280, in __step
    result = coro.send(None)
  File "/usr/local/lib/python3.8/site-packages/uvicorn/lifespan/on.py", line 84, in main
    await app(scope, self.receive, self.send)
  File "/usr/local/lib/python3.8/site-packages/uvicorn/middleware/proxy_headers.py", line 75, in __call__
    return await self.app(scope, receive, send)
  File "/usr/local/lib/python3.8/site-packages/fastapi/applications.py", line 208, in __call__
    await super().__call__(scope, receive, send)
  File "/usr/local/lib/python3.8/site-packages/starlette/applications.py", line 112, in __call__
    await self.middleware_stack(scope, receive, send)
  File "/usr/local/lib/python3.8/site-packages/starlette/middleware/errors.py", line 146, in __call__
    await self.app(scope, receive, send)
  File "/usr/local/lib/python3.8/site-packages/starlette/exceptions.py", line 58, in __call__
    await self.app(scope, receive, send)
  File "/usr/local/lib/python3.8/site-packages/starlette/routing.py", line 645, in __call__
    await self.lifespan(scope, receive, send)
  File "/usr/local/lib/python3.8/site-packages/starlette/routing.py", line 621, in lifespan
    async with self.lifespan_context(app):
  File "/usr/local/lib/python3.8/site-packages/starlette/routing.py", line 518, in __aenter__
    await self._router.startup()
  File "/usr/local/lib/python3.8/site-packages/starlette/routing.py", line 598, in startup
    await handler()
  File "/code/src/api/main.py", line 137, in startup_event
    queue = await RabbitMQQueue.setupConnection(
  File "/code/src/api/message_queues/rabbitmq/message_queue.py", line 28, in setupConnection
    logger.info("Connected")
  File "/usr/local/lib/python3.8/logging/__init__.py", line 1446, in info
    self._log(INFO, msg, args, **kwargs)
  File "/usr/local/lib/python3.8/logging/__init__.py", line 1589, in _log
    self.handle(record)
  File "/usr/local/lib/python3.8/logging/__init__.py", line 1599, in handle
    self.callHandlers(record)
  File "/usr/local/lib/python3.8/logging/__init__.py", line 1661, in callHandlers
    hdlr.handle(record)
  File "/usr/local/lib/python3.8/logging/__init__.py", line 954, in handle
    self.emit(record)
  File "/code/src/api/logger/LogCollectorAPIHandler.py", line 23, in emit
    self.handleError(record)
Message: 'Connected'
Arguments: ()
INFO:     Application startup complete.
2023-03-28 09:10:04,241 [INFO] uvicorn.error: Application startup complete.
Application startup complete.
--- Logging error ---
Traceback (most recent call last):
  File "/usr/local/lib/python3.8/site-packages/urllib3/connection.py", line 174, in _new_conn
    conn = connection.create_connection(
  File "/usr/local/lib/python3.8/site-packages/urllib3/util/connection.py", line 72, in create_connection
    for res in socket.getaddrinfo(host, port, family, socket.SOCK_STREAM):
  File "/usr/local/lib/python3.8/socket.py", line 918, in getaddrinfo
    for res in _socket.getaddrinfo(host, port, family, type, proto, flags):
socket.gaierror: [Errno -2] Name or service not known

During handling of the above exception, another exception occurred:

Traceback (most recent call last):
  File "/usr/local/lib/python3.8/site-packages/urllib3/connectionpool.py", line 703, in urlopen
    httplib_response = self._make_request(
  File "/usr/local/lib/python3.8/site-packages/urllib3/connectionpool.py", line 398, in _make_request
    conn.request(method, url, **httplib_request_kw)
  File "/usr/local/lib/python3.8/site-packages/urllib3/connection.py", line 239, in request
    super(HTTPConnection, self).request(method, url, body=body, headers=headers)
  File "/usr/local/lib/python3.8/http/client.py", line 1256, in request
    self._send_request(method, url, body, headers, encode_chunked)
  File "/usr/local/lib/python3.8/http/client.py", line 1302, in _send_request
    self.endheaders(body, encode_chunked=encode_chunked)
  File "/usr/local/lib/python3.8/http/client.py", line 1251, in endheaders
    self._send_output(message_body, encode_chunked=encode_chunked)
  File "/usr/local/lib/python3.8/http/client.py", line 1011, in _send_output
    self.send(msg)
  File "/usr/local/lib/python3.8/http/client.py", line 951, in send
    self.connect()
  File "/usr/local/lib/python3.8/site-packages/urllib3/connection.py", line 205, in connect
    conn = self._new_conn()
  File "/usr/local/lib/python3.8/site-packages/urllib3/connection.py", line 186, in _new_conn
    raise NewConnectionError(
urllib3.exceptions.NewConnectionError: <urllib3.connection.HTTPConnection object at 0x7f3ff68b4760>: Failed to establish a new connection: [Errno -2] Name or service not known

During handling of the above exception, another exception occurred:

Traceback (most recent call last):
  File "/usr/local/lib/python3.8/site-packages/requests/adapters.py", line 489, in send
    resp = conn.urlopen(
  File "/usr/local/lib/python3.8/site-packages/urllib3/connectionpool.py", line 787, in urlopen
    retries = retries.increment(
  File "/usr/local/lib/python3.8/site-packages/urllib3/util/retry.py", line 592, in increment
    raise MaxRetryError(_pool, url, error or ResponseError(cause))
urllib3.exceptions.MaxRetryError: HTTPConnectionPool(host='log-collector-api-service', port=3001): Max retries exceeded with url: /logs (Caused by NewConnectionError('<urllib3.connection.HTTPConnection object at 0x7f3ff68b4760>: Failed to establish a new connection: [Errno -2] Name or service not known'))

During handling of the above exception, another exception occurred:

Traceback (most recent call last):
  File "/code/src/api/logger/LogCollectorAPIHandler.py", line 19, in emit
    requests.post(
  File "/usr/local/lib/python3.8/site-packages/requests/api.py", line 115, in post
    return request("post", url, data=data, json=json, **kwargs)
  File "/usr/local/lib/python3.8/site-packages/requests/api.py", line 59, in request
    return session.request(method=method, url=url, **kwargs)
  File "/usr/local/lib/python3.8/site-packages/requests/sessions.py", line 587, in request
    resp = self.send(prep, **send_kwargs)
  File "/usr/local/lib/python3.8/site-packages/requests/sessions.py", line 701, in send
    r = adapter.send(request, **kwargs)
  File "/usr/local/lib/python3.8/site-packages/requests/adapters.py", line 565, in send
    raise ConnectionError(e, request=request)
requests.exceptions.ConnectionError: HTTPConnectionPool(host='log-collector-api-service', port=3001): Max retries exceeded with url: /logs (Caused by NewConnectionError('<urllib3.connection.HTTPConnection object at 0x7f3ff68b4760>: Failed to establish a new connection: [Errno -2] Name or service not known'))
Call stack:
  File "/usr/local/lib/python3.8/runpy.py", line 194, in _run_module_as_main
    return _run_code(code, main_globals, None,
  File "/usr/local/lib/python3.8/runpy.py", line 87, in _run_code
    exec(code, run_globals)
  File "/code/src/api/__main__.py", line 4, in <module>
    start_app()
  File "/usr/local/lib/python3.8/site-packages/click/core.py", line 1128, in __call__
    return self.main(*args, **kwargs)
  File "/usr/local/lib/python3.8/site-packages/click/core.py", line 1053, in main
    rv = self.invoke(ctx)
  File "/usr/local/lib/python3.8/site-packages/click/core.py", line 1395, in invoke
    return ctx.invoke(self.callback, **ctx.params)
  File "/usr/local/lib/python3.8/site-packages/click/core.py", line 754, in invoke
    return __callback(*args, **kwargs)
  File "/code/src/api/__init__.py", line 33, in start_app
    uvicorn.run(app="api.main:app", workers=1, host="0.0.0.0", port=8000)
  File "/usr/local/lib/python3.8/site-packages/uvicorn/main.py", line 447, in run
    server.run()
  File "/usr/local/lib/python3.8/site-packages/uvicorn/server.py", line 68, in run
    return asyncio.run(self.serve(sockets=sockets))
  File "/usr/local/lib/python3.8/site-packages/nest_asyncio.py", line 35, in run
    return loop.run_until_complete(task)
  File "/usr/local/lib/python3.8/site-packages/nest_asyncio.py", line 84, in run_until_complete
    self._run_once()
  File "/usr/local/lib/python3.8/site-packages/nest_asyncio.py", line 120, in _run_once
    handle._run()
  File "/usr/local/lib/python3.8/asyncio/events.py", line 81, in _run
    self._context.run(self._callback, *self._args)
  File "/usr/local/lib/python3.8/asyncio/tasks.py", line 360, in __wakeup
    self.__step()
  File "/usr/local/lib/python3.8/site-packages/nest_asyncio.py", line 196, in step
    step_orig(task, exc)
  File "/usr/local/lib/python3.8/asyncio/tasks.py", line 280, in __step
    result = coro.send(None)
  File "/usr/local/lib/python3.8/site-packages/uvicorn/server.py", line 86, in serve
    await self.startup(sockets=sockets)
  File "/usr/local/lib/python3.8/site-packages/uvicorn/server.py", line 97, in startup
    await self.lifespan.startup()
  File "/usr/local/lib/python3.8/site-packages/uvicorn/lifespan/on.py", line 59, in startup
    self.logger.info("Application startup complete.")
  File "/usr/local/lib/python3.8/logging/__init__.py", line 1446, in info
    self._log(INFO, msg, args, **kwargs)
  File "/usr/local/lib/python3.8/logging/__init__.py", line 1589, in _log
    self.handle(record)
  File "/usr/local/lib/python3.8/logging/__init__.py", line 1599, in handle
    self.callHandlers(record)
  File "/usr/local/lib/python3.8/logging/__init__.py", line 1661, in callHandlers
    hdlr.handle(record)
  File "/usr/local/lib/python3.8/logging/__init__.py", line 954, in handle
    self.emit(record)
  File "/code/src/api/logger/LogCollectorAPIHandler.py", line 23, in emit
    self.handleError(record)
Message: 'Application startup complete.'
Arguments: ()
INFO:     Uvicorn running on http://0.0.0.0:8000 (Press CTRL+C to quit)
2023-03-28 09:10:04,249 [INFO] uvicorn.error: Uvicorn running on http://0.0.0.0:8000 (Press CTRL+C to quit)
Uvicorn running on http://0.0.0.0:8000 (Press CTRL+C to quit)
--- Logging error ---
Traceback (most recent call last):
  File "/usr/local/lib/python3.8/site-packages/urllib3/connection.py", line 174, in _new_conn
    conn = connection.create_connection(
  File "/usr/local/lib/python3.8/site-packages/urllib3/util/connection.py", line 72, in create_connection
    for res in socket.getaddrinfo(host, port, family, socket.SOCK_STREAM):
  File "/usr/local/lib/python3.8/socket.py", line 918, in getaddrinfo
    for res in _socket.getaddrinfo(host, port, family, type, proto, flags):
socket.gaierror: [Errno -2] Name or service not known

During handling of the above exception, another exception occurred:

Traceback (most recent call last):
  File "/usr/local/lib/python3.8/site-packages/urllib3/connectionpool.py", line 703, in urlopen
    httplib_response = self._make_request(
  File "/usr/local/lib/python3.8/site-packages/urllib3/connectionpool.py", line 398, in _make_request
    conn.request(method, url, **httplib_request_kw)
  File "/usr/local/lib/python3.8/site-packages/urllib3/connection.py", line 239, in request
    super(HTTPConnection, self).request(method, url, body=body, headers=headers)
  File "/usr/local/lib/python3.8/http/client.py", line 1256, in request
    self._send_request(method, url, body, headers, encode_chunked)
  File "/usr/local/lib/python3.8/http/client.py", line 1302, in _send_request
    self.endheaders(body, encode_chunked=encode_chunked)
  File "/usr/local/lib/python3.8/http/client.py", line 1251, in endheaders
    self._send_output(message_body, encode_chunked=encode_chunked)
  File "/usr/local/lib/python3.8/http/client.py", line 1011, in _send_output
    self.send(msg)
  File "/usr/local/lib/python3.8/http/client.py", line 951, in send
    self.connect()
  File "/usr/local/lib/python3.8/site-packages/urllib3/connection.py", line 205, in connect
    conn = self._new_conn()
  File "/usr/local/lib/python3.8/site-packages/urllib3/connection.py", line 186, in _new_conn
    raise NewConnectionError(
urllib3.exceptions.NewConnectionError: <urllib3.connection.HTTPConnection object at 0x7f3ff68b45b0>: Failed to establish a new connection: [Errno -2] Name or service not known

During handling of the above exception, another exception occurred:

Traceback (most recent call last):
  File "/usr/local/lib/python3.8/site-packages/requests/adapters.py", line 489, in send
    resp = conn.urlopen(
  File "/usr/local/lib/python3.8/site-packages/urllib3/connectionpool.py", line 787, in urlopen
    retries = retries.increment(
  File "/usr/local/lib/python3.8/site-packages/urllib3/util/retry.py", line 592, in increment
    raise MaxRetryError(_pool, url, error or ResponseError(cause))
urllib3.exceptions.MaxRetryError: HTTPConnectionPool(host='log-collector-api-service', port=3001): Max retries exceeded with url: /logs (Caused by NewConnectionError('<urllib3.connection.HTTPConnection object at 0x7f3ff68b45b0>: Failed to establish a new connection: [Errno -2] Name or service not known'))

During handling of the above exception, another exception occurred:

Traceback (most recent call last):
  File "/code/src/api/logger/LogCollectorAPIHandler.py", line 19, in emit
    requests.post(
  File "/usr/local/lib/python3.8/site-packages/requests/api.py", line 115, in post
    return request("post", url, data=data, json=json, **kwargs)
  File "/usr/local/lib/python3.8/site-packages/requests/api.py", line 59, in request
    return session.request(method=method, url=url, **kwargs)
  File "/usr/local/lib/python3.8/site-packages/requests/sessions.py", line 587, in request
    resp = self.send(prep, **send_kwargs)
  File "/usr/local/lib/python3.8/site-packages/requests/sessions.py", line 701, in send
    r = adapter.send(request, **kwargs)
  File "/usr/local/lib/python3.8/site-packages/requests/adapters.py", line 565, in send
    raise ConnectionError(e, request=request)
requests.exceptions.ConnectionError: HTTPConnectionPool(host='log-collector-api-service', port=3001): Max retries exceeded with url: /logs (Caused by NewConnectionError('<urllib3.connection.HTTPConnection object at 0x7f3ff68b45b0>: Failed to establish a new connection: [Errno -2] Name or service not known'))
Call stack:
  File "/usr/local/lib/python3.8/runpy.py", line 194, in _run_module_as_main
    return _run_code(code, main_globals, None,
  File "/usr/local/lib/python3.8/runpy.py", line 87, in _run_code
    exec(code, run_globals)
  File "/code/src/api/__main__.py", line 4, in <module>
    start_app()
  File "/usr/local/lib/python3.8/site-packages/click/core.py", line 1128, in __call__
    return self.main(*args, **kwargs)
  File "/usr/local/lib/python3.8/site-packages/click/core.py", line 1053, in main
    rv = self.invoke(ctx)
  File "/usr/local/lib/python3.8/site-packages/click/core.py", line 1395, in invoke
    return ctx.invoke(self.callback, **ctx.params)
  File "/usr/local/lib/python3.8/site-packages/click/core.py", line 754, in invoke
    return __callback(*args, **kwargs)
  File "/code/src/api/__init__.py", line 33, in start_app
    uvicorn.run(app="api.main:app", workers=1, host="0.0.0.0", port=8000)
  File "/usr/local/lib/python3.8/site-packages/uvicorn/main.py", line 447, in run
    server.run()
  File "/usr/local/lib/python3.8/site-packages/uvicorn/server.py", line 68, in run
    return asyncio.run(self.serve(sockets=sockets))
  File "/usr/local/lib/python3.8/site-packages/nest_asyncio.py", line 35, in run
    return loop.run_until_complete(task)
  File "/usr/local/lib/python3.8/site-packages/nest_asyncio.py", line 84, in run_until_complete
    self._run_once()
  File "/usr/local/lib/python3.8/site-packages/nest_asyncio.py", line 120, in _run_once
    handle._run()
  File "/usr/local/lib/python3.8/asyncio/events.py", line 81, in _run
    self._context.run(self._callback, *self._args)
  File "/usr/local/lib/python3.8/site-packages/nest_asyncio.py", line 196, in step
    step_orig(task, exc)
  File "/usr/local/lib/python3.8/asyncio/tasks.py", line 280, in __step
    result = coro.send(None)
  File "/usr/local/lib/python3.8/site-packages/uvicorn/server.py", line 86, in serve
    await self.startup(sockets=sockets)
  File "/usr/local/lib/python3.8/site-packages/uvicorn/server.py", line 176, in startup
    self._log_started_message(listeners)
  File "/usr/local/lib/python3.8/site-packages/uvicorn/server.py", line 217, in _log_started_message
    logger.info(
  File "/usr/local/lib/python3.8/logging/__init__.py", line 1446, in info
    self._log(INFO, msg, args, **kwargs)
  File "/usr/local/lib/python3.8/logging/__init__.py", line 1589, in _log
    self.handle(record)
  File "/usr/local/lib/python3.8/logging/__init__.py", line 1599, in handle
    self.callHandlers(record)
  File "/usr/local/lib/python3.8/logging/__init__.py", line 1661, in callHandlers
    hdlr.handle(record)
  File "/usr/local/lib/python3.8/logging/__init__.py", line 954, in handle
    self.emit(record)
  File "/code/src/api/logger/LogCollectorAPIHandler.py", line 23, in emit
    self.handleError(record)
Message: 'Uvicorn running on %s://%s:%d (Press CTRL+C to quit)'
Arguments: ('http', '0.0.0.0', 8000)
Message processing queue connected
2023-03-28 09:10:04,257 [INFO] api.message_queues.rabbitmq.message_queue: Message processing queue connected
--- Logging error ---
Traceback (most recent call last):
  File "/usr/local/lib/python3.8/site-packages/urllib3/connection.py", line 174, in _new_conn
    conn = connection.create_connection(
  File "/usr/local/lib/python3.8/site-packages/urllib3/util/connection.py", line 72, in create_connection
    for res in socket.getaddrinfo(host, port, family, socket.SOCK_STREAM):
  File "/usr/local/lib/python3.8/socket.py", line 918, in getaddrinfo
    for res in _socket.getaddrinfo(host, port, family, type, proto, flags):
socket.gaierror: [Errno -2] Name or service not known

During handling of the above exception, another exception occurred:

Traceback (most recent call last):
  File "/usr/local/lib/python3.8/site-packages/urllib3/connectionpool.py", line 703, in urlopen
    httplib_response = self._make_request(
  File "/usr/local/lib/python3.8/site-packages/urllib3/connectionpool.py", line 398, in _make_request
    conn.request(method, url, **httplib_request_kw)
  File "/usr/local/lib/python3.8/site-packages/urllib3/connection.py", line 239, in request
    super(HTTPConnection, self).request(method, url, body=body, headers=headers)
  File "/usr/local/lib/python3.8/http/client.py", line 1256, in request
    self._send_request(method, url, body, headers, encode_chunked)
  File "/usr/local/lib/python3.8/http/client.py", line 1302, in _send_request
    self.endheaders(body, encode_chunked=encode_chunked)
  File "/usr/local/lib/python3.8/http/client.py", line 1251, in endheaders
    self._send_output(message_body, encode_chunked=encode_chunked)
  File "/usr/local/lib/python3.8/http/client.py", line 1011, in _send_output
    self.send(msg)
  File "/usr/local/lib/python3.8/http/client.py", line 951, in send
    self.connect()
  File "/usr/local/lib/python3.8/site-packages/urllib3/connection.py", line 205, in connect
    conn = self._new_conn()
  File "/usr/local/lib/python3.8/site-packages/urllib3/connection.py", line 186, in _new_conn
    raise NewConnectionError(
urllib3.exceptions.NewConnectionError: <urllib3.connection.HTTPConnection object at 0x7f3ff68bb7c0>: Failed to establish a new connection: [Errno -2] Name or service not known

During handling of the above exception, another exception occurred:

Traceback (most recent call last):
  File "/usr/local/lib/python3.8/site-packages/requests/adapters.py", line 489, in send
    resp = conn.urlopen(
  File "/usr/local/lib/python3.8/site-packages/urllib3/connectionpool.py", line 787, in urlopen
    retries = retries.increment(
  File "/usr/local/lib/python3.8/site-packages/urllib3/util/retry.py", line 592, in increment
    raise MaxRetryError(_pool, url, error or ResponseError(cause))
urllib3.exceptions.MaxRetryError: HTTPConnectionPool(host='log-collector-api-service', port=3001): Max retries exceeded with url: /logs (Caused by NewConnectionError('<urllib3.connection.HTTPConnection object at 0x7f3ff68bb7c0>: Failed to establish a new connection: [Errno -2] Name or service not known'))

During handling of the above exception, another exception occurred:

Traceback (most recent call last):
  File "/code/src/api/logger/LogCollectorAPIHandler.py", line 19, in emit
    requests.post(
  File "/usr/local/lib/python3.8/site-packages/requests/api.py", line 115, in post
    return request("post", url, data=data, json=json, **kwargs)
  File "/usr/local/lib/python3.8/site-packages/requests/api.py", line 59, in request
    return session.request(method=method, url=url, **kwargs)
  File "/usr/local/lib/python3.8/site-packages/requests/sessions.py", line 587, in request
    resp = self.send(prep, **send_kwargs)
  File "/usr/local/lib/python3.8/site-packages/requests/sessions.py", line 701, in send
    r = adapter.send(request, **kwargs)
  File "/usr/local/lib/python3.8/site-packages/requests/adapters.py", line 565, in send
    raise ConnectionError(e, request=request)
requests.exceptions.ConnectionError: HTTPConnectionPool(host='log-collector-api-service', port=3001): Max retries exceeded with url: /logs (Caused by NewConnectionError('<urllib3.connection.HTTPConnection object at 0x7f3ff68bb7c0>: Failed to establish a new connection: [Errno -2] Name or service not known'))
Call stack:
  File "/usr/local/lib/python3.8/runpy.py", line 194, in _run_module_as_main
    return _run_code(code, main_globals, None,
  File "/usr/local/lib/python3.8/runpy.py", line 87, in _run_code
    exec(code, run_globals)
  File "/code/src/api/__main__.py", line 4, in <module>
    start_app()
  File "/usr/local/lib/python3.8/site-packages/click/core.py", line 1128, in __call__
    return self.main(*args, **kwargs)
  File "/usr/local/lib/python3.8/site-packages/click/core.py", line 1053, in main
    rv = self.invoke(ctx)
  File "/usr/local/lib/python3.8/site-packages/click/core.py", line 1395, in invoke
    return ctx.invoke(self.callback, **ctx.params)
  File "/usr/local/lib/python3.8/site-packages/click/core.py", line 754, in invoke
    return __callback(*args, **kwargs)
  File "/code/src/api/__init__.py", line 33, in start_app
    uvicorn.run(app="api.main:app", workers=1, host="0.0.0.0", port=8000)
  File "/usr/local/lib/python3.8/site-packages/uvicorn/main.py", line 447, in run
    server.run()
  File "/usr/local/lib/python3.8/site-packages/uvicorn/server.py", line 68, in run
    return asyncio.run(self.serve(sockets=sockets))
  File "/usr/local/lib/python3.8/site-packages/nest_asyncio.py", line 35, in run
    return loop.run_until_complete(task)
  File "/usr/local/lib/python3.8/site-packages/nest_asyncio.py", line 84, in run_until_complete
    self._run_once()
  File "/usr/local/lib/python3.8/site-packages/nest_asyncio.py", line 120, in _run_once
    handle._run()
  File "/usr/local/lib/python3.8/asyncio/events.py", line 81, in _run
    self._context.run(self._callback, *self._args)
  File "/usr/local/lib/python3.8/asyncio/tasks.py", line 360, in __wakeup
    self.__step()
  File "/usr/local/lib/python3.8/site-packages/nest_asyncio.py", line 196, in step
    step_orig(task, exc)
  File "/usr/local/lib/python3.8/asyncio/tasks.py", line 280, in __step
    result = coro.send(None)
  File "/code/src/api/main.py", line 116, in process_queue
    async for message, err, result in queue.process(process_message):
  File "/code/src/api/message_queues/rabbitmq/message_queue.py", line 44, in process
    logger.info("Message processing queue connected")
  File "/usr/local/lib/python3.8/logging/__init__.py", line 1446, in info
    self._log(INFO, msg, args, **kwargs)
  File "/usr/local/lib/python3.8/logging/__init__.py", line 1589, in _log
    self.handle(record)
  File "/usr/local/lib/python3.8/logging/__init__.py", line 1599, in handle
    self.callHandlers(record)
  File "/usr/local/lib/python3.8/logging/__init__.py", line 1661, in callHandlers
    hdlr.handle(record)
  File "/usr/local/lib/python3.8/logging/__init__.py", line 954, in handle
    self.emit(record)
  File "/code/src/api/logger/LogCollectorAPIHandler.py", line 23, in emit
    self.handleError(record)
Message: 'Message processing queue connected'
Arguments: ()
